16/08/21 (22:06:10) | ERROR: Exception when sending signal 9 to pid 101665
16/08/21 (22:06:10) | ERROR: [Errno 1] Operation not permitted
Traceback (most recent call last):
  File "/usr/bin/bpytop", line 5459, in process_keys
    os.kill(pid, sig)
PermissionError: [Errno 1] Operation not permitted
16/08/21 (22:06:20) | ERROR: Input thread failed with exception: (5, 'Input/output error')
Traceback (most recent call last):
  File "/usr/bin/bpytop", line 985, in _get_key
    input_key = ""
  File "/usr/bin/bpytop", line 778, in __exit__
    termios.tcsetattr(self.stream, termios.TCSANOW, self.original_stty)
termios.error: (5, 'Input/output error')
07/09/21 (23:06:42) | ERROR: <urlopen error timed out>
Traceback (most recent call last):
  File "/usr/lib/python3.9/urllib/request.py", line 1346, in do_open
    h.request(req.get_method(), req.selector, req.data, headers,
  File "/usr/lib/python3.9/http/client.py", line 1257, in request
    self._send_request(method, url, body, headers, encode_chunked)
  File "/usr/lib/python3.9/http/client.py", line 1303, in _send_request
    self.endheaders(body, encode_chunked=encode_chunked)
  File "/usr/lib/python3.9/http/client.py", line 1252, in endheaders
    self._send_output(message_body, encode_chunked=encode_chunked)
  File "/usr/lib/python3.9/http/client.py", line 1012, in _send_output
    self.send(msg)
  File "/usr/lib/python3.9/http/client.py", line 952, in send
    self.connect()
  File "/usr/lib/python3.9/http/client.py", line 1419, in connect
    super().connect()
  File "/usr/lib/python3.9/http/client.py", line 923, in connect
    self.sock = self._create_connection(
  File "/usr/lib/python3.9/socket.py", line 843, in create_connection
    raise err
  File "/usr/lib/python3.9/socket.py", line 831, in create_connection
    sock.connect(sa)
socket.timeout: timed out

During handling of the above exception, another exception occurred:

Traceback (most recent call last):
  File "/usr/bin/bpytop", line 5009, in _checker
    with urllib.request.urlopen("https://github.com/aristocratos/bpytop/raw/master/bpytop.py", timeout=5) as source: # type: ignore
  File "/usr/lib/python3.9/urllib/request.py", line 214, in urlopen
    return opener.open(url, data, timeout)
  File "/usr/lib/python3.9/urllib/request.py", line 517, in open
    response = self._open(req, data)
  File "/usr/lib/python3.9/urllib/request.py", line 534, in _open
    result = self._call_chain(self.handle_open, protocol, protocol +
  File "/usr/lib/python3.9/urllib/request.py", line 494, in _call_chain
    result = func(*args)
  File "/usr/lib/python3.9/urllib/request.py", line 1389, in https_open
    return self.do_open(http.client.HTTPSConnection, req,
  File "/usr/lib/python3.9/urllib/request.py", line 1349, in do_open
    raise URLError(err)
urllib.error.URLError: <urlopen error timed out>
30/09/21 (04:19:35) | ERROR: <urlopen error [Errno -2] Name or service not known>
Traceback (most recent call last):
  File "/usr/lib/python3.9/urllib/request.py", line 1346, in do_open
    h.request(req.get_method(), req.selector, req.data, headers,
  File "/usr/lib/python3.9/http/client.py", line 1279, in request
    self._send_request(method, url, body, headers, encode_chunked)
  File "/usr/lib/python3.9/http/client.py", line 1325, in _send_request
    self.endheaders(body, encode_chunked=encode_chunked)
  File "/usr/lib/python3.9/http/client.py", line 1274, in endheaders
    self._send_output(message_body, encode_chunked=encode_chunked)
  File "/usr/lib/python3.9/http/client.py", line 1034, in _send_output
    self.send(msg)
  File "/usr/lib/python3.9/http/client.py", line 974, in send
    self.connect()
  File "/usr/lib/python3.9/http/client.py", line 1441, in connect
    super().connect()
  File "/usr/lib/python3.9/http/client.py", line 945, in connect
    self.sock = self._create_connection(
  File "/usr/lib/python3.9/socket.py", line 823, in create_connection
    for res in getaddrinfo(host, port, 0, SOCK_STREAM):
  File "/usr/lib/python3.9/socket.py", line 954, in getaddrinfo
    for res in _socket.getaddrinfo(host, port, family, type, proto, flags):
socket.gaierror: [Errno -2] Name or service not known

During handling of the above exception, another exception occurred:

Traceback (most recent call last):
  File "/usr/bin/bpytop", line 5009, in _checker
    with urllib.request.urlopen("https://github.com/aristocratos/bpytop/raw/master/bpytop.py", timeout=5) as source: # type: ignore
  File "/usr/lib/python3.9/urllib/request.py", line 214, in urlopen
    return opener.open(url, data, timeout)
  File "/usr/lib/python3.9/urllib/request.py", line 517, in open
    response = self._open(req, data)
  File "/usr/lib/python3.9/urllib/request.py", line 534, in _open
    result = self._call_chain(self.handle_open, protocol, protocol +
  File "/usr/lib/python3.9/urllib/request.py", line 494, in _call_chain
    result = func(*args)
  File "/usr/lib/python3.9/urllib/request.py", line 1389, in https_open
    return self.do_open(http.client.HTTPSConnection, req,
  File "/usr/lib/python3.9/urllib/request.py", line 1349, in do_open
    raise URLError(err)
urllib.error.URLError: <urlopen error [Errno -2] Name or service not known>
16/10/21 (16:55:38) | ERROR: <urlopen error [Errno 111] Connection refused>
Traceback (most recent call last):
  File "/usr/lib/python3.9/urllib/request.py", line 1346, in do_open
    h.request(req.get_method(), req.selector, req.data, headers,
  File "/usr/lib/python3.9/http/client.py", line 1279, in request
    self._send_request(method, url, body, headers, encode_chunked)
  File "/usr/lib/python3.9/http/client.py", line 1325, in _send_request
    self.endheaders(body, encode_chunked=encode_chunked)
  File "/usr/lib/python3.9/http/client.py", line 1274, in endheaders
    self._send_output(message_body, encode_chunked=encode_chunked)
  File "/usr/lib/python3.9/http/client.py", line 1034, in _send_output
    self.send(msg)
  File "/usr/lib/python3.9/http/client.py", line 974, in send
    self.connect()
  File "/usr/lib/python3.9/http/client.py", line 1441, in connect
    super().connect()
  File "/usr/lib/python3.9/http/client.py", line 945, in connect
    self.sock = self._create_connection(
  File "/usr/lib/python3.9/socket.py", line 844, in create_connection
    raise err
  File "/usr/lib/python3.9/socket.py", line 832, in create_connection
    sock.connect(sa)
ConnectionRefusedError: [Errno 111] Connection refused

During handling of the above exception, another exception occurred:

Traceback (most recent call last):
  File "/usr/bin/bpytop", line 5009, in _checker
    with urllib.request.urlopen("https://github.com/aristocratos/bpytop/raw/master/bpytop.py", timeout=5) as source: # type: ignore
  File "/usr/lib/python3.9/urllib/request.py", line 214, in urlopen
    return opener.open(url, data, timeout)
  File "/usr/lib/python3.9/urllib/request.py", line 517, in open
    response = self._open(req, data)
  File "/usr/lib/python3.9/urllib/request.py", line 534, in _open
    result = self._call_chain(self.handle_open, protocol, protocol +
  File "/usr/lib/python3.9/urllib/request.py", line 494, in _call_chain
    result = func(*args)
  File "/usr/lib/python3.9/urllib/request.py", line 1389, in https_open
    return self.do_open(http.client.HTTPSConnection, req,
  File "/usr/lib/python3.9/urllib/request.py", line 1349, in do_open
    raise URLError(err)
urllib.error.URLError: <urlopen error [Errno 111] Connection refused>
